{
  "DataVersion": 3955,
  "size": [
    24,
    8,
    24
  ],
  "palette": [
    {
      "Name": "cobblefurnies:lab_floor"
    },
    {
      "Name": "minecraft:smooth_quartz"
    },
    {
      "Name": "cobbleventure_theme_blocks:house_cream_base_wall"
    },
    {
      "Name": "minecraft:air"
    },
    {
      "Name": "minecraft:bookshelf"
    },
    {
      "Name": "minecraft:quartz_block"
    },
    {
      "Name": "minecraft:azalea_leaves",
      "Properties": {
        "distance": "1",
        "persistent": "true",
        "waterlogged": "false"
      }
    },
    {
      "Name": "minecraft:black_concrete"
    },
    {
      "Name": "minecraft:light_blue_stained_glass"
    },
    {
      "Name": "minecraft:sea_lantern"
    },
    {
      "Name": "minecraft:smooth_quartz_slab",
      "Properties": {
        "type": "bottom",
        "waterlogged": "false"
      }
    },
    {
      "Name": "minecraft:cyan_concrete"
    },
    {
      "Name": "minecraft:cyan_carpet"
    },
    {
      "Name": "minecraft:iron_door",
      "Properties": {
        "facing": "north",
        "half": "lower",
        "hinge": "left",
        "open": "false",
        "powered": "false"
      }
    },
    {
      "Name": "minecraft:iron_door",
      "Properties": {
        "facing": "north",
        "half": "upper",
        "hinge": "left",
        "open": "false",
        "powered": "false"
      }
    },
    {
      "Name": "minecraft:cyan_stained_glass"
    }
  ],
  "blocks": [
    {
      "pos": [
        0,
        0,
        0
      ],
      "state": 0
    },
    {
      "pos": [
        0,
        0,
        1
      ],
      "state": 0
    },
    {
      "pos": [
        0,
        0,
        2
      ],
      "state": 0
    },
    {
      "pos": [
        0,
        0,
        3
      ],
      "state": 0
    },
    {
      "pos": [
        0,
        0,
        4
      ],
      "state": 0
    },
    {
      "pos": [
        0,
        0,
        5
      ],
      "state": 0
    },
    {
      "pos": [
        0,
        0,
        6
      ],
      "state": 0
    },
    {
      "pos": [
        0,
        0,
        7
      ],
      "state": 0
    },
    {
      "pos": [
        0,
        0,
        8
      ],
      "state": 0
    },
    {
      "pos": [
        0,
        0,
        9
      ],
      "state": 0
    },
    {
      "pos": [
        0,
        0,
        10
      ],
      "state": 0
    },
    {
      "pos": [
        0,
        0,
        11
      ],
      "state": 0
    },
    {
      "pos": [
        0,
        0,
        12
      ],
      "state": 0
    },
    {
      "pos": [
        0,
        0,
        13
      ],
      "state": 0
    },
    {
      "pos": [
        0,
        0,
        14
      ],
      "state": 0
    },
    {
      "pos": [
        0,
        0,
        15
      ],
      "state": 0
    },
    {
      "pos": [
        0,
        0,
        16
      ],
      "state": 0
    },
    {
      "pos": [
        0,
        0,
        17
      ],
      "state": 0
    },
    {
      "pos": [
        0,
        0,
        18
      ],
      "state": 0
    },
    {
      "pos": [
        0,
        0,
        19
      ],
      "state": 0
    },
    {
      "pos": [
        0,
        0,
        20
      ],
      "state": 0
    },
    {
      "pos": [
        0,
        0,
        21
      ],
      "state": 0
    },
    {
      "pos": [
        0,
        0,
        22
      ],
      "state": 0
    },
    {
      "pos": [
        0,
        0,
        23
      ],
      "state": 0
    },
    {
      "pos": [
        0,
        1,
        0
      ],
      "state": 1
    },
    {
      "pos": [
        0,
        1,
        1
      ],
      "state": 1
    },
    {
      "pos": [
        0,
        1,
        2
      ],
      "state": 1
    },
    {
      "pos": [
        0,
        1,
        3
      ],
      "state": 1
    },
    {
      "pos": [
        0,
        1,
        4
      ],
      "state": 1
    },
    {
      "pos": [
        0,
        1,
        5
      ],
      "state": 1
    },
    {
      "pos": [
        0,
        1,
        6
      ],
      "state": 1
    },
    {
      "pos": [
        0,
        1,
        7
      ],
      "state": 1
    },
    {
      "pos": [
        0,
        1,
        8
      ],
      "state": 1
    },
    {
      "pos": [
        0,
        1,
        9
      ],
      "state": 1
    },
    {
      "pos": [
        0,
        1,
        10
      ],
      "state": 1
    },
    {
      "pos": [
        0,
        1,
        11
      ],
      "state": 1
    },
    {
      "pos": [
        0,
        1,
        12
      ],
      "state": 1
    },
    {
      "pos": [
        0,
        1,
        13
      ],
      "state": 1
    },
    {
      "pos": [
        0,
        1,
        14
      ],
      "state": 1
    },
    {
      "pos": [
        0,
        1,
        15
      ],
      "state": 1
    },
    {
      "pos": [
        0,
        1,
        16
      ],
      "state": 1
    },
    {
      "pos": [
        0,
        1,
        17
      ],
      "state": 1
    },
    {
      "pos": [
        0,
        1,
        18
      ],
      "state": 1
    },
    {
      "pos": [
        0,
        1,
        19
      ],
      "state": 1
    },
    {
      "pos": [
        0,
        1,
        20
      ],
      "state": 1
    },
    {
      "pos": [
        0,
        1,
        21
      ],
      "state": 1
    },
    {
      "pos": [
        0,
        1,
        22
      ],
      "state": 1
    },
    {
      "pos": [
        0,
        1,
        23
      ],
      "state": 1
    },
    {
      "pos": [
        0,
        2,
        0
      ],
      "state": 2
    },
    {
      "pos": [
        0,
        2,
        1
      ],
      "state": 2
    },
    {
      "pos": [
        0,
        2,
        2
      ],
      "state": 2
    },
    {
      "pos": [
        0,
        2,
        3
      ],
      "state": 2
    },
    {
      "pos": [
        0,
        2,
        4
      ],
      "state": 2
    },
    {
      "pos": [
        0,
        2,
        5
      ],
      "state": 2
    },
    {
      "pos": [
        0,
        2,
        6
      ],
      "state": 2
    },
    {
      "pos": [
        0,
        2,
        7
      ],
      "state": 2
    },
    {
      "pos": [
        0,
        2,
        8
      ],
      "state": 2
    },
    {
      "pos": [
        0,
        2,
        9
      ],
      "state": 2
    },
    {
      "pos": [
        0,
        2,
        10
      ],
      "state": 2
    },
    {
      "pos": [
        0,
        2,
        11
      ],
      "state": 2
    },
    {
      "pos": [
        0,
        2,
        12
      ],
      "state": 2
    },
    {
      "pos": [
        0,
        2,
        13
      ],
      "state": 2
    },
    {
      "pos": [
        0,
        2,
        14
      ],
      "state": 2
    },
    {
      "pos": [
        0,
        2,
        15
      ],
      "state": 2
    },
    {
      "pos": [
        0,
        2,
        16
      ],
      "state": 2
    },
    {
      "pos": [
        0,
        2,
        17
      ],
      "state": 2
    },
    {
      "pos": [
        0,
        2,
        18
      ],
      "state": 2
    },
    {
      "pos": [
        0,
        2,
        19
      ],
      "state": 2
    },
    {
      "pos": [
        0,
        2,
        20
      ],
      "state": 2
    },
    {
      "pos": [
        0,
        2,
        21
      ],
      "state": 2
    },
    {
      "pos": [
        0,
        2,
        22
      ],
      "state": 2
    },
    {
      "pos": [
        0,
        2,
        23
      ],
      "state": 2
    },
    {
      "pos": [
        0,
        3,
        0
      ],
      "state": 2
    },
    {
      "pos": [
        0,
        3,
        1
      ],
      "state": 2
    },
    {
      "pos": [
        0,
        3,
        2
      ],
      "state": 2
    },
    {
      "pos": [
        0,
        3,
        3
      ],
      "state": 2
    },
    {
      "pos": [
        0,
        3,
        4
      ],
      "state": 2
    },
    {
      "pos": [
        0,
        3,
        5
      ],
      "state": 2
    },
    {
      "pos": [
        0,
        3,
        6
      ],
      "state": 2
    },
    {
      "pos": [
        0,
        3,
        7
      ],
      "state": 2
    },
    {
      "pos": [
        0,
        3,
        8
      ],
      "state": 2
    },
    {
      "pos": [
        0,
        3,
        9
      ],
      "state": 2
    },
    {
      "pos": [
        0,
        3,
        10
      ],
      "state": 2
    },
    {
      "pos": [
        0,
        3,
        11
      ],
      "state": 2
    },
    {
      "pos": [
        0,
        3,
        12
      ],
      "state": 2
    },
    {
      "pos": [
        0,
        3,
        13
      ],
      "state": 2
    },
    {
      "pos": [
        0,
        3,
        14
      ],
      "state": 2
    },
    {
      "pos": [
        0,
        3,
        15
      ],
      "state": 2
    },
    {
      "pos": [
        0,
        3,
        16
      ],
      "state": 2
    },
    {
      "pos": [
        0,
        3,
        17
      ],
      "state": 2
    },
    {
      "pos": [
        0,
        3,
        18
      ],
      "state": 2
    },
    {
      "pos": [
        0,
        3,
        19
      ],
      "state": 2
    },
    {
      "pos": [
        0,
        3,
        20
      ],
      "state": 2
    },
    {
      "pos": [
        0,
        3,
        21
      ],
      "state": 2
    },
    {
      "pos": [
        0,
        3,
        22
      ],
      "state": 2
    },
    {
      "pos": [
        0,
        3,
        23
      ],
      "state": 2
    },
    {
      "pos": [
        0,
        4,
        0
      ],
      "state": 2
    },
    {
      "pos": [
        0,
        4,
        1
      ],
      "state": 2
    },
    {
      "pos": [
        0,
        4,
        2
      ],
      "state": 2
    },
    {
      "pos": [
        0,
        4,
        3
      ],
      "state": 2
    },
    {
      "pos": [
        0,
        4,
        4
      ],
      "state": 2
    },
    {
      "pos": [
        0,
        4,
        5
      ],
      "state": 2
    },
    {
      "pos": [
        0,
        4,
        6
      ],
      "state": 2
    },
    {
      "pos": [
        0,
        4,
        7
      ],
      "state": 2
    },
    {
      "pos": [
        0,
        4,
        8
      ],
      "state": 2
    },
    {
      "pos": [
        0,
        4,
        9
      ],
      "state": 2
    },
    {
      "pos": [
        0,
        4,
        10
      ],
      "state": 2
    },
    {
      "pos": [
        0,
        4,
        11
      ],
      "state": 2
    },
    {
      "pos": [
        0,
        4,
        12
      ],
      "state": 2
    },
    {
      "pos": [
        0,
        4,
        13
      ],
      "state": 2
    },
    {
      "pos": [
        0,
        4,
        14
      ],
      "state": 2
    },
    {
      "pos": [
        0,
        4,
        15
      ],
      "state": 2
    },
    {
      "pos": [
        0,
        4,
        16
      ],
      "state": 2
    },
    {
      "pos": [
        0,
        4,
        17
      ],
      "state": 2
    },
    {
      "pos": [
        0,
        4,
        18
      ],
      "state": 2
    },
    {
      "pos": [
        0,
        4,
        19
      ],
      "state": 2
    },
    {
      "pos": [
        0,
        4,
        20
      ],
      "state": 2
    },
    {
      "pos": [
        0,
        4,
        21
      ],
      "state": 2
    },
    {
      "pos": [
        0,
        4,
        22
      ],
      "state": 2
    },
    {
      "pos": [
        0,
        4,
        23
      ],
      "state": 2
    },
    {
      "pos": [
        0,
        5,
        0
      ],
      "state": 2
    },
    {
      "pos": [
        0,
        5,
        1
      ],
      "state": 2
    },
    {
      "pos": [
        0,
        5,
        2
      ],
      "state": 2
    },
    {
      "pos": [
        0,
        5,
        3
      ],
      "state": 2
    },
    {
      "pos": [
        0,
        5,
        4
      ],
      "state": 2
    },
    {
      "pos": [
        0,
        5,
        5
      ],
      "state": 2
    },
    {
      "pos": [
        0,
        5,
        6
      ],
      "state": 2
    },
    {
      "pos": [
        0,
        5,
        7
      ],
      "state": 2
    },
    {
      "pos": [
        0,
        5,
        8
      ],
      "state": 2
    },
    {
      "pos": [
        0,
        5,
        9
      ],
      "state": 2
    },
    {
      "pos": [
        0,
        5,
        10
      ],
      "state": 2
    },
    {
      "pos": [
        0,
        5,
        11
      ],
      "state": 2
    },
    {
      "pos": [
        0,
        5,
        12
      ],
      "state": 2
    },
    {
      "pos": [
        0,
        5,
        13
      ],
      "state": 2
    },
    {
      "pos": [
        0,
        5,
        14
      ],
      "state": 2
    },
    {
      "pos": [
        0,
        5,
        15
      ],
      "state": 2
    },
    {
      "pos": [
        0,
        5,
        16
      ],
      "state": 2
    },
    {
      "pos": [
        0,
        5,
        17
      ],
      "state": 2
    },
    {
      "pos": [
        0,
        5,
        18
      ],
      "state": 2
    },
    {
      "pos": [
        0,
        5,
        19
      ],
      "state": 2
    },
    {
      "pos": [
        0,
        5,
        20
      ],
      "state": 2
    },
    {
      "pos": [
        0,
        5,
        21
      ],
      "state": 2
    },
    {
      "pos": [
        0,
        5,
        22
      ],
      "state": 2
    },
    {
      "pos": [
        0,
        5,
        23
      ],
      "state": 2
    },
    {
      "pos": [
        0,
        6,
        0
      ],
      "state": 2
    },
    {
      "pos": [
        0,
        6,
        1
      ],
      "state": 2
    },
    {
      "pos": [
        0,
        6,
        2
      ],
      "state": 2
    },
    {
      "pos": [
        0,
        6,
        3
      ],
      "state": 2
    },
    {
      "pos": [
        0,
        6,
        4
      ],
      "state": 2
    },
    {
      "pos": [
        0,
        6,
        5
      ],
      "state": 2
    },
    {
      "pos": [
        0,
        6,
        6
      ],
      "state": 2
    },
    {
      "pos": [
        0,
        6,
        7
      ],
      "state": 2
    },
    {
      "pos": [
        0,
        6,
        8
      ],
      "state": 2
    },
    {
      "pos": [
        0,
        6,
        9
      ],
      "state": 2
    },
    {
      "pos": [
        0,
        6,
        10
      ],
      "state": 2
    },
    {
      "pos": [
        0,
        6,
        11
      ],
      "state": 2
    },
    {
      "pos": [
        0,
        6,
        12
      ],
      "state": 2
    },
    {
      "pos": [
        0,
        6,
        13
      ],
      "state": 2
    },
    {
      "pos": [
        0,
        6,
        14
      ],
      "state": 2
    },
    {
      "pos": [
        0,
        6,
        15
      ],
      "state": 2
    },
    {
      "pos": [
        0,
        6,
        16
      ],
      "state": 2
    },
    {
      "pos": [
        0,
        6,
        17
      ],
      "state": 2
    },
    {
      "pos": [
        0,
        6,
        18
      ],
      "state": 2
    },
    {
      "pos": [
        0,
        6,
        19
      ],
      "state": 2
    },
    {
      "pos": [
        0,
        6,
        20
      ],
      "state": 2
    },
    {
      "pos": [
        0,
        6,
        21
      ],
      "state": 2
    },
    {
      "pos": [
        0,
        6,
        22
      ],
      "state": 2
    },
    {
      "pos": [
        0,
        6,
        23
      ],
      "state": 2
    },
    {
      "pos": [
        0,
        7,
        0
      ],
      "state": 1
    },
    {
      "pos": [
        0,
        7,
        1
      ],
      "state": 1
    },
    {
      "pos": [
        0,
        7,
        2
      ],
      "state": 1
    },
    {
      "pos": [
        0,
        7,
        3
      ],
      "state": 1
    },
    {
      "pos": [
        0,
        7,
        4
      ],
      "state": 1
    },
    {
      "pos": [
        0,
        7,
        5
      ],
      "state": 1
    },
    {
      "pos": [
        0,
        7,
        6
      ],
      "state": 1
    },
    {
      "pos": [
        0,
        7,
        7
      ],
      "state": 1
    },
    {
      "pos": [
        0,
        7,
        8
      ],
      "state": 1
    },
    {
      "pos": [
        0,
        7,
        9
      ],
      "state": 1
    },
    {
      "pos": [
        0,
        7,
        10
      ],
      "state": 1
    },
    {
      "pos": [
        0,
        7,
        11
      ],
      "state": 1
    },
    {
      "pos": [
        0,
        7,
        12
      ],
      "state": 1
    },
    {
      "pos": [
        0,
        7,
        13
      ],
      "state": 1
    },
    {
      "pos": [
        0,
        7,
        14
      ],
      "state": 1
    },
    {
      "pos": [
        0,
        7,
        15
      ],
      "state": 1
    },
    {
      "pos": [
        0,
        7,
        16
      ],
      "state": 1
    },
    {
      "pos": [
        0,
        7,
        17
      ],
      "state": 1
    },
    {
      "pos": [
        0,
        7,
        18
      ],
      "state": 1
    },
    {
      "pos": [
        0,
        7,
        19
      ],
      "state": 1
    },
    {
      "pos": [
        0,
        7,
        20
      ],
      "state": 1
    },
    {
      "pos": [
        0,
        7,
        21
      ],
      "state": 1
    },
    {
      "pos": [
        0,
        7,
        22
      ],
      "state": 1
    },
    {
      "pos": [
        0,
        7,
        23
      ],
      "state": 1
    },
    {
      "pos": [
        1,
        0,
        0
      ],
      "state": 0
    },
    {
      "pos": [
        1,
        0,
        1
      ],
      "state": 0
    },
    {
      "pos": [
        1,
        0,
        2
      ],
      "state": 0
    },
    {
      "pos": [
        1,
        0,
        3
      ],
      "state": 0
    },
    {
      "pos": [
        1,
        0,
        4
      ],
      "state": 0
    },
    {
      "pos": [
        1,
        0,
        5
      ],
      "state": 0
    },
    {
      "pos": [
        1,
        0,
        6
      ],
      "state": 0
    },
    {
      "pos": [
        1,
        0,
        7
      ],
      "state": 0
    },
    {
      "pos": [
        1,
        0,
        8
      ],
      "state": 0
    },
    {
      "pos": [
        1,
        0,
        9
      ],
      "state": 0
    },
    {
      "pos": [
        1,
        0,
        10
      ],
      "state": 0
    },
    {
      "pos": [
        1,
        0,
        11
      ],
      "state": 0
    },
    {
      "pos": [
        1,
        0,
        12
      ],
      "state": 0
    },
    {
      "pos": [
        1,
        0,
        13
      ],
      "state": 0
    },
    {
      "pos": [
        1,
        0,
        14
      ],
      "state": 0
    },
    {
      "pos": [
        1,
        0,
        15
      ],
      "state": 0
    },
    {
      "pos": [
        1,
        0,
        16
      ],
      "state": 0
    },
    {
      "pos": [
        1,
        0,
        17
      ],
      "state": 0
    },
    {
      "pos": [
        1,
        0,
        18
      ],
      "state": 0
    },
    {
      "pos": [
        1,
        0,
        19
      ],
      "state": 0
    },
    {
      "pos": [
        1,
        0,
        20
      ],
      "state": 0
    },
    {
      "pos": [
        1,
        0,
        21
      ],
      "state": 0
    },
    {
      "pos": [
        1,
        0,
        22
      ],
      "state": 0
    },
    {
      "pos": [
        1,
        0,
        23
      ],
      "state": 0
    },
    {
      "pos": [
        1,
        1,
        0
      ],
      "state": 1
    },
    {
      "pos": [
        1,
        1,
        1
      ],
      "state": 3
    },
    {
      "pos": [
        1,
        1,
        2
      ],
      "state": 3
    },
    {
      "pos": [
        1,
        1,
        3
      ],
      "state": 3
    },
    {
      "pos": [
        1,
        1,
        4
      ],
      "state": 3
    },
    {
      "pos": [
        1,
        1,
        5
      ],
      "state": 3
    },
    {
      "pos": [
        1,
        1,
        6
      ],
      "state": 3
    },
    {
      "pos": [
        1,
        1,
        7
      ],
      "state": 3
    },
    {
      "pos": [
        1,
        1,
        8
      ],
      "state": 3
    },
    {
      "pos": [
        1,
        1,
        9
      ],
      "state": 3
    },
    {
      "pos": [
        1,
        1,
        10
      ],
      "state": 3
    },
    {
      "pos": [
        1,
        1,
        11
      ],
      "state": 3
    },
    {
      "pos": [
        1,
        1,
        12
      ],
      "state": 3
    },
    {
      "pos": [
        1,
        1,
        13
      ],
      "state": 3
    },
    {
      "pos": [
        1,
        1,
        14
      ],
      "state": 3
    },
    {
      "pos": [
        1,
        1,
        15
      ],
      "state": 3
    },
    {
      "pos": [
        1,
        1,
        16
      ],
      "state": 3
    },
    {
      "pos": [
        1,
        1,
        17
      ],
      "state": 3
    },
    {
      "pos": [
        1,
        1,
        18
      ],
      "state": 3
    },
    {
      "pos": [
        1,
        1,
        19
      ],
      "state": 3
    },
    {
      "pos": [
        1,
        1,
        20
      ],
      "state": 3
    },
    {
      "pos": [
        1,
        1,
        21
      ],
      "state": 3
    },
    {
      "pos": [
        1,
        1,
        22
      ],
      "state": 3
    },
    {
      "pos": [
        1,
        1,
        23
      ],
      "state": 1
    },
    {
      "pos": [
        1,
        2,
        0
      ],
      "state": 2
    },
    {
      "pos": [
        1,
        2,
        1
      ],
      "state": 3
    },
    {
      "pos": [
        1,
        2,
        2
      ],
      "state": 3
    },
    {
      "pos": [
        1,
        2,
        3
      ],
      "state": 3
    },
    {
      "pos": [
        1,
        2,
        4
      ],
      "state": 3
    },
    {
      "pos": [
        1,
        2,
        5
      ],
      "state": 3
    },
    {
      "pos": [
        1,
        2,
        6
      ],
      "state": 3
    },
    {
      "pos": [
        1,
        2,
        7
      ],
      "state": 3
    },
    {
      "pos": [
        1,
        2,
        8
      ],
      "state": 3
    },
    {
      "pos": [
        1,
        2,
        9
      ],
      "state": 3
    },
    {
      "pos": [
        1,
        2,
        10
      ],
      "state": 3
    },
    {
      "pos": [
        1,
        2,
        11
      ],
      "state": 3
    },
    {
      "pos": [
        1,
        2,
        12
      ],
      "state": 3
    },
    {
      "pos": [
        1,
        2,
        13
      ],
      "state": 3
    },
    {
      "pos": [
        1,
        2,
        14
      ],
      "state": 3
    },
    {
      "pos": [
        1,
        2,
        15
      ],
      "state": 3
    },
    {
      "pos": [
        1,
        2,
        16
      ],
      "state": 3
    },
    {
      "pos": [
        1,
        2,
        17
      ],
      "state": 3
    },
    {
      "pos": [
        1,
        2,
        18
      ],
      "state": 3
    },
    {
      "pos": [
        1,
        2,
        19
      ],
      "state": 3
    },
    {
      "pos": [
        1,
        2,
        20
      ],
      "state": 3
    },
    {
      "pos": [
        1,
        2,
        21
      ],
      "state": 3
    },
    {
      "pos": [
        1,
        2,
        22
      ],
      "state": 3
    },
    {
      "pos": [
        1,
        2,
        23
      ],
      "state": 2
    },
    {
      "pos": [
        1,
        3,
        0
      ],
      "state": 2
    },
    {
      "pos": [
        1,
        3,
        1
      ],
      "state": 3
    },
    {
      "pos": [
        1,
        3,
        2
      ],
      "state": 3
    },
    {
      "pos": [
        1,
        3,
        3
      ],
      "state": 3
    },
    {
      "pos": [
        1,
        3,
        4
      ],
      "state": 3
    },
    {
      "pos": [
        1,
        3,
        5
      ],
      "state": 3
    },
    {
      "pos": [
        1,
        3,
        6
      ],
      "state": 3
    },
    {
      "pos": [
        1,
        3,
        7
      ],
      "state": 3
    },
    {
      "pos": [
        1,
        3,
        8
      ],
      "state": 3
    },
    {
      "pos": [
        1,
        3,
        9
      ],
      "state": 3
    },
    {
      "pos": [
        1,
        3,
        10
      ],
      "state": 3
    },
    {
      "pos": [
        1,
        3,
        11
      ],
      "state": 3
    },
    {
      "pos": [
        1,
        3,
        12
      ],
      "state": 3
    },
    {
      "pos": [
        1,
        3,
        13
      ],
      "state": 3
    },
    {
      "pos": [
        1,
        3,
        14
      ],
      "state": 3
    },
    {
      "pos": [
        1,
        3,
        15
      ],
      "state": 3
    },
    {
      "pos": [
        1,
        3,
        16
      ],
      "state": 3
    },
    {
      "pos": [
        1,
        3,
        17
      ],
      "state": 3
    },
    {
      "pos": [
        1,
        3,
        18
      ],
      "state": 3
    },
    {
      "pos": [
        1,
        3,
        19
      ],
      "state": 3
    },
    {
      "pos": [
        1,
        3,
        20
      ],
      "state": 3
    },
    {
      "pos": [
        1,
        3,
        21
      ],
      "state": 3
    },
    {
      "pos": [
        1,
        3,
        22
      ],
      "state": 3
    },
    {
      "pos": [
        1,
        3,
        23
      ],
      "state": 2
    },
    {
      "pos": [
        1,
        4,
        0
      ],
      "state": 2
    },
    {
      "pos": [
        1,
        4,
        1
      ],
      "state": 3
    },
    {
      "pos": [
        1,
        4,
        2
      ],
      "state": 3
    },
    {
      "pos": [
        1,
        4,
        3
      ],
      "state": 3
    },
    {
      "pos": [
        1,
        4,
        4
      ],
      "state": 3
    },
    {
      "pos": [
        1,
        4,
        5
      ],
      "state": 3
    },
    {
      "pos": [
        1,
        4,
        6
      ],
      "state": 3
    },
    {
      "pos": [
        1,
        4,
        7
      ],
      "state": 3
    },
    {
      "pos": [
        1,
        4,
        8
      ],
      "state": 3
    },
    {
      "pos": [
        1,
        4,
        9
      ],
      "state": 3
    },
    {
      "pos": [
        1,
        4,
        10
      ],
      "state": 3
    },
    {
      "pos": [
        1,
        4,
        11
      ],
      "state": 3
    },
    {
      "pos": [
        1,
        4,
        12
      ],
      "state": 3
    },
    {
      "pos": [
        1,
        4,
        13
      ],
      "state": 3
    },
    {
      "pos": [
        1,
        4,
        14
      ],
      "state": 3
    },
    {
      "pos": [
        1,
        4,
        15
      ],
      "state": 3
    },
    {
      "pos": [
        1,
        4,
        16
      ],
      "state": 3
    },
    {
      "pos": [
        1,
        4,
        17
      ],
      "state": 3
    },
    {
      "pos": [
        1,
        4,
        18
      ],
      "state": 3
    },
    {
      "pos": [
        1,
        4,
        19
      ],
      "state": 3
    },
    {
      "pos": [
        1,
        4,
        20
      ],
      "state": 3
    },
    {
      "pos": [
        1,
        4,
        21
      ],
      "state": 3
    },
    {
      "pos": [
        1,
        4,
        22
      ],
      "state": 3
    },
    {
      "pos": [
        1,
        4,
        23
      ],
      "state": 2
    },
    {
      "pos": [
        1,
        5,
        0
      ],
      "state": 2
    },
    {
      "pos": [
        1,
        5,
        1
      ],
      "state": 3
    },
    {
      "pos": [
        1,
        5,
        2
      ],
      "state": 3
    },
    {
      "pos": [
        1,
        5,
        3
      ],
      "state": 3
    },
    {
      "pos": [
        1,
        5,
        4
      ],
      "state": 3
    },
    {
      "pos": [
        1,
        5,
        5
      ],
      "state": 3
    },
    {
      "pos": [
        1,
        5,
        6
      ],
      "state": 3
    },
    {
      "pos": [
        1,
        5,
        7
      ],
      "state": 3
    },
    {
      "pos": [
        1,
        5,
        8
      ],
      "state": 3
    },
    {
      "pos": [
        1,
        5,
        9
      ],
      "state": 3
    },
    {
      "pos": [
        1,
        5,
        10
      ],
      "state": 3
    },
    {
      "pos": [
        1,
        5,
        11
      ],
      "state": 3
    },
    {
      "pos": [
        1,
        5,
        12
      ],
      "state": 3
    },
    {
      "pos": [
        1,
        5,
        13
      ],
      "state": 3
    },
    {
      "pos": [
        1,
        5,
        14
      ],
      "state": 3
    },
    {
      "pos": [
        1,
        5,
        15
      ],
      "state": 3
    },
    {
      "pos": [
        1,
        5,
        16
      ],
      "state": 3
    },
    {
      "pos": [
        1,
        5,
        17
      ],
      "state": 3
    },
    {
      "pos": [
        1,
        5,
        18
      ],
      "state": 3
    },
    {
      "pos": [
        1,
        5,
        19
      ],
      "state": 3
    },
    {
      "pos": [
        1,
        5,
        20
      ],
      "state": 3
    },
    {
      "pos": [
        1,
        5,
        21
      ],
      "state": 3
    },
    {
      "pos": [
        1,
        5,
        22
      ],
      "state": 3
    },
    {
      "pos": [
        1,
        5,
        23
      ],
      "state": 2
    },
    {
      "pos": [
        1,
        6,
        0
      ],
      "state": 2
    },
    {
      "pos": [
        1,
        6,
        1
      ],
      "state": 3
    },
    {
      "pos": [
        1,
        6,
        2
      ],
      "state": 3
    },
    {
      "pos": [
        1,
        6,
        3
      ],
      "state": 3
    },
    {
      "pos": [
        1,
        6,
        4
      ],
      "state": 3
    },
    {
      "pos": [
        1,
        6,
        5
      ],
      "state": 3
    },
    {
      "pos": [
        1,
        6,
        6
      ],
      "state": 3
    },
    {
      "pos": [
        1,
        6,
        7
      ],
      "state": 3
    },
    {
      "pos": [
        1,
        6,
        8
      ],
      "state": 3
    },
    {
      "pos": [
        1,
        6,
        9
      ],
      "state": 3
    },
    {
      "pos": [
        1,
        6,
        10
      ],
      "state": 3
    },
    {
      "pos": [
        1,
        6,
        11
      ],
      "state": 3
    },
    {
      "pos": [
        1,
        6,
        12
      ],
      "state": 3
    },
    {
      "pos": [
        1,
        6,
        13
      ],
      "state": 3
    },
    {
      "pos": [
        1,
        6,
        14
      ],
      "state": 3
    },
    {
      "pos": [
        1,
        6,
        15
      ],
      "state": 3
    },
    {
      "pos": [
        1,
        6,
        16
      ],
      "state": 3
    },
    {
      "pos": [
        1,
        6,
        17
      ],
      "state": 3
    },
    {
      "pos": [
        1,
        6,
        18
      ],
      "state": 3
    },
    {
      "pos": [
        1,
        6,
        19
      ],
      "state": 3
    },
    {
      "pos": [
        1,
        6,
        20
      ],
      "state": 3
    },
    {
      "pos": [
        1,
        6,
        21
      ],
      "state": 3
    },
    {
      "pos": [
        1,
        6,
        22
      ],
      "state": 3
    },
    {
      "pos": [
        1,
        6,
        23
      ],
      "state": 2
    },
    {
      "pos": [
        1,
        7,
        0
      ],
      "state": 1
    },
    {
      "pos": [
        1,
        7,
        1
      ],
      "state": 1
    },
    {
      "pos": [
        1,
        7,
        2
      ],
      "state": 1
    },
    {
      "pos": [
        1,
        7,
        3
      ],
      "state": 1
    },
    {
      "pos": [
        1,
        7,
        4
      ],
      "state": 1
    },
    {
      "pos": [
        1,
        7,
        5
      ],
      "state": 1
    },
    {
      "pos": [
        1,
        7,
        6
      ],
      "state": 1
    },
    {
      "pos": [
        1,
        7,
        7
      ],
      "state": 1
    },
    {
      "pos": [
        1,
        7,
        8
      ],
      "state": 1
    },
    {
      "pos": [
        1,
        7,
        9
      ],
      "state": 1
    },
    {
      "pos": [
        1,
        7,
        10
      ],
      "state": 1
    },
    {
      "pos": [
        1,
        7,
        11
      ],
      "state": 1
    },
    {
      "pos": [
        1,
        7,
        12
      ],
      "state": 1
    },
    {
      "pos": [
        1,
        7,
        13
      ],
      "state": 1
    },
    {
      "pos": [
        1,
        7,
        14
      ],
      "state": 1
    },
    {
      "pos": [
        1,
        7,
        15
      ],
      "state": 1
    },
    {
      "pos": [
        1,
        7,
        16
      ],
      "state": 1
    },
    {
      "pos": [
        1,
        7,
        17
      ],
      "state": 1
    },
    {
      "pos": [
        1,
        7,
        18
      ],
      "state": 1
    },
    {
      "pos": [
        1,
        7,
        19
      ],
      "state": 1
    },
    {
      "pos": [
        1,
        7,
        20
      ],
      "state": 1
    },
    {
      "pos": [
        1,
        7,
        21
      ],
      "state": 1
    },
    {
      "pos": [
        1,
        7,
        22
      ],
      "state": 1
    },
    {
      "pos": [
        1,
        7,
        23
      ],
      "state": 1
    },
    {
      "pos": [
        2,
        0,
        0
      ],
      "state": 0
    },
    {
      "pos": [
        2,
        0,
        1
      ],
      "state": 0
    },
    {
      "pos": [
        2,
        0,
        2
      ],
      "state": 0
    },
    {
      "pos": [
        2,
        0,
        3
      ],
      "state": 0
    },
    {
      "pos": [
        2,
        0,
        4
      ],
      "state": 0
    },
    {
      "pos": [
        2,
        0,
        5
      ],
      "state": 0
    },
    {
      "pos": [
        2,
        0,
        6
      ],
      "state": 0
    },
    {
      "pos": [
        2,
        0,
        7
      ],
      "state": 0
    },
    {
      "pos": [
        2,
        0,
        8
      ],
      "state": 0
    },
    {
      "pos": [
        2,
        0,
        9
      ],
      "state": 0
    },
    {
      "pos": [
        2,
        0,
        10
      ],
      "state": 0
    },
    {
      "pos": [
        2,
        0,
        11
      ],
      "state": 0
    },
    {
      "pos": [
        2,
        0,
        12
      ],
      "state": 0
    },
    {
      "pos": [
        2,
        0,
        13
      ],
      "state": 0
    },
    {
      "pos": [
        2,
        0,
        14
      ],
      "state": 0
    },
    {
      "pos": [
        2,
        0,
        15
      ],
      "state": 0
    },
    {
      "pos": [
        2,
        0,
        16
      ],
      "state": 0
    },
    {
      "pos": [
        2,
        0,
        17
      ],
      "state": 0
    },
    {
      "pos": [
        2,
        0,
        18
      ],
      "state": 0
    },
    {
      "pos": [
        2,
        0,
        19
      ],
      "state": 0
    },
    {
      "pos": [
        2,
        0,
        20
      ],
      "state": 0
    },
    {
      "pos": [
        2,
        0,
        21
      ],
      "state": 0
    },
    {
      "pos": [
        2,
        0,
        22
      ],
      "state": 0
    },
    {
      "pos": [
        2,
        0,
        23
      ],
      "state": 0
    },
    {
      "pos": [
        2,
        1,
        0
      ],
      "state": 1
    },
    {
      "pos": [
        2,
        1,
        1
      ],
      "state": 3
    },
    {
      "pos": [
        2,
        1,
        2
      ],
      "state": 3
    },
    {
      "pos": [
        2,
        1,
        3
      ],
      "state": 3
    },
    {
      "pos": [
        2,
        1,
        4
      ],
      "state": 3
    },
    {
      "pos": [
        2,
        1,
        5
      ],
      "state": 4
    },
    {
      "pos": [
        2,
        1,
        6
      ],
      "state": 4
    },
    {
      "pos": [
        2,
        1,
        7
      ],
      "state": 4
    },
    {
      "pos": [
        2,
        1,
        8
      ],
      "state": 4
    },
    {
      "pos": [
        2,
        1,
        9
      ],
      "state": 3
    },
    {
      "pos": [
        2,
        1,
        10
      ],
      "state": 3
    },
    {
      "pos": [
        2,
        1,
        11
      ],
      "state": 3
    },
    {
      "pos": [
        2,
        1,
        12
      ],
      "state": 3
    },
    {
      "pos": [
        2,
        1,
        13
      ],
      "state": 3
    },
    {
      "pos": [
        2,
        1,
        14
      ],
      "state": 3
    },
    {
      "pos": [
        2,
        1,
        15
      ],
      "state": 3
    },
    {
      "pos": [
        2,
        1,
        16
      ],
      "state": 3
    },
    {
      "pos": [
        2,
        1,
        17
      ],
      "state": 3
    },
    {
      "pos": [
        2,
        1,
        18
      ],
      "state": 3
    },
    {
      "pos": [
        2,
        1,
        19
      ],
      "state": 3
    },
    {
      "pos": [
        2,
        1,
        20
      ],
      "state": 5
    },
    {
      "pos": [
        2,
        1,
        21
      ],
      "state": 3
    },
    {
      "pos": [
        2,
        1,
        22
      ],
      "state": 3
    },
    {
      "pos": [
        2,
        1,
        23
      ],
      "state": 1
    },
    {
      "pos": [
        2,
        2,
        0
      ],
      "state": 2
    },
    {
      "pos": [
        2,
        2,
        1
      ],
      "state": 3
    },
    {
      "pos": [
        2,
        2,
        2
      ],
      "state": 3
    },
    {
      "pos": [
        2,
        2,
        3
      ],
      "state": 3
    },
    {
      "pos": [
        2,
        2,
        4
      ],
      "state": 3
    },
    {
      "pos": [
        2,
        2,
        5
      ],
      "state": 4
    },
    {
      "pos": [
        2,
        2,
        6
      ],
      "state": 4
    },
    {
      "pos": [
        2,
        2,
        7
      ],
      "state": 4
    },
    {
      "pos": [
        2,
        2,
        8
      ],
      "state": 4
    },
    {
      "pos": [
        2,
        2,
        9
      ],
      "state": 3
    },
    {
      "pos": [
        2,
        2,
        10
      ],
      "state": 3
    },
    {
      "pos": [
        2,
        2,
        11
      ],
      "state": 3
    },
    {
      "pos": [
        2,
        2,
        12
      ],
      "state": 3
    },
    {
      "pos": [
        2,
        2,
        13
      ],
      "state": 3
    },
    {
      "pos": [
        2,
        2,
        14
      ],
      "state": 3
    },
    {
      "pos": [
        2,
        2,
        15
      ],
      "state": 3
    },
    {
      "pos": [
        2,
        2,
        16
      ],
      "state": 3
    },
    {
      "pos": [
        2,
        2,
        17
      ],
      "state": 3
    },
    {
      "pos": [
        2,
        2,
        18
      ],
      "state": 3
    },
    {
      "pos": [
        2,
        2,
        19
      ],
      "state": 3
    },
    {
      "pos": [
        2,
        2,
        20
      ],
      "state": 6
    },
    {
      "pos": [
        2,
        2,
        21
      ],
      "state": 3
    },
    {
      "pos": [
        2,
        2,
        22
      ],
      "state": 3
    },
    {
      "pos": [
        2,
        2,
        23
      ],
      "state": 2
    },
    {
      "pos": [
        2,
        3,
        0
      ],
      "state": 2
    },
    {
      "pos": [
        2,
        3,
        1
      ],
      "state": 3
    },
    {
      "pos": [
        2,
        3,
        2
      ],
      "state": 3
    },
    {
      "pos": [
        2,
        3,
        3
      ],
      "state": 3
    },
    {
      "pos": [
        2,
        3,
        4
      ],
      "state": 3
    },
    {
      "pos": [
        2,
        3,
        5
      ],
      "state": 4
    },
    {
      "pos": [
        2,
        3,
        6
      ],
      "state": 4
    },
    {
      "pos": [
        2,
        3,
        7
      ],
      "state": 4
    },
    {
      "pos": [
        2,
        3,
        8
      ],
      "state": 4
    },
    {
      "pos": [
        2,
        3,
        9
      ],
      "state": 3
    },
    {
      "pos": [
        2,
        3,
        10
      ],
      "state": 3
    },
    {
      "pos": [
        2,
        3,
        11
      ],
      "state": 3
    },
    {
      "pos": [
        2,
        3,
        12
      ],
      "state": 3
    },
    {
      "pos": [
        2,
        3,
        13
      ],
      "state": 3
    },
    {
      "pos": [
        2,
        3,
        14
      ],
      "state": 3
    },
    {
      "pos": [
        2,
        3,
        15
      ],
      "state": 3
    },
    {
      "pos": [
        2,
        3,
        16
      ],
      "state": 3
    },
    {
      "pos": [
        2,
        3,
        17
      ],
      "state": 3
    },
    {
      "pos": [
        2,
        3,
        18
      ],
      "state": 3
    },
    {
      "pos": [
        2,
        3,
        19
      ],
      "state": 3
    },
    {
      "pos": [
        2,
        3,
        20
      ],
      "state": 3
    },
    {
      "pos": [
        2,
        3,
        21
      ],
      "state": 3
    },
    {
      "pos": [
        2,
        3,
        22
      ],
      "state": 3
    },
    {
      "pos": [
        2,
        3,
        23
      ],
      "state": 2
    },
    {
      "pos": [
        2,
        4,
        0
      ],
      "state": 2
    },
    {
      "pos": [
        2,
        4,
        1
      ],
      "state": 3
    },
    {
      "pos": [
        2,
        4,
        2
      ],
      "state": 3
    },
    {
      "pos": [
        2,
        4,
        3
      ],
      "state": 3
    },
    {
      "pos": [
        2,
        4,
        4
      ],
      "state": 3
    },
    {
      "pos": [
        2,
        4,
        5
      ],
      "state": 3
    },
    {
      "pos": [
        2,
        4,
        6
      ],
      "state": 3
    },
    {
      "pos": [
        2,
        4,
        7
      ],
      "state": 3
    },
    {
      "pos": [
        2,
        4,
        8
      ],
      "state": 3
    },
    {
      "pos": [
        2,
        4,
        9
      ],
      "state": 3
    },
    {
      "pos": [
        2,
        4,
        10
      ],
      "state": 3
    },
    {
      "pos": [
        2,
        4,
        11
      ],
      "state": 3
    },
    {
      "pos": [
        2,
        4,
        12
      ],
      "state": 3
    },
    {
      "pos": [
        2,
        4,
        13
      ],
      "state": 3
    },
    {
      "pos": [
        2,
        4,
        14
      ],
      "state": 3
    },
    {
      "pos": [
        2,
        4,
        15
      ],
      "state": 3
    },
    {
      "pos": [
        2,
        4,
        16
      ],
      "state": 3
    },
    {
      "pos": [
        2,
        4,
        17
      ],
      "state": 3
    },
    {
      "pos": [
        2,
        4,
        18
      ],
      "state": 3
    },
    {
      "pos": [
        2,
        4,
        19
      ],
      "state": 3
    },
    {
      "pos": [
        2,
        4,
        20
      ],
      "state": 3
    },
    {
      "pos": [
        2,
        4,
        21
      ],
      "state": 3
    },
    {
      "pos": [
        2,
        4,
        22
      ],
      "state": 3
    },
    {
      "pos": [
        2,
        4,
        23
      ],
      "state": 2
    },
    {
      "pos": [
        2,
        5,
        0
      ],
      "state": 2
    },
    {
      "pos": [
        2,
        5,
        1
      ],
      "state": 3
    },
    {
      "pos": [
        2,
        5,
        2
      ],
      "state": 3
    },
    {
      "pos": [
        2,
        5,
        3
      ],
      "state": 3
    },
    {
      "pos": [
        2,
        5,
        4
      ],
      "state": 3
    },
    {
      "pos": [
        2,
        5,
        5
      ],
      "state": 3
    },
    {
      "pos": [
        2,
        5,
        6
      ],
      "state": 3
    },
    {
      "pos": [
        2,
        5,
        7
      ],
      "state": 3
    },
    {
      "pos": [
        2,
        5,
        8
      ],
      "state": 3
    },
    {
      "pos": [
        2,
        5,
        9
      ],
      "state": 3
    },
    {
      "pos": [
        2,
        5,
        10
      ],
      "state": 3
    },
    {
      "pos": [
        2,
        5,
        11
      ],
      "state": 3
    },
    {
      "pos": [
        2,
        5,
        12
      ],
      "state": 3
    },
    {
      "pos": [
        2,
        5,
        13
      ],
      "state": 3
    },
    {
      "pos": [
        2,
        5,
        14
      ],
      "state": 3
    },
    {
      "pos": [
        2,
        5,
        15
      ],
      "state": 3
    },
    {
      "pos": [
        2,
        5,
        16
      ],
      "state": 3
    },
    {
      "pos": [
        2,
        5,
        17
      ],
      "state": 3
    },
    {
      "pos": [
        2,
        5,
        18
      ],
      "state": 3
    },
    {
      "pos": [
        2,
        5,
        19
      ],
      "state": 3
    },
    {
      "pos": [
        2,
        5,
        20
      ],
      "state": 3
    },
    {
      "pos": [
        2,
        5,
        21
      ],
      "state": 3
    },
    {
      "pos": [
        2,
        5,
        22
      ],
      "state": 3
    },
    {
      "pos": [
        2,
        5,
        23
      ],
      "state": 2
    },
    {
      "pos": [
        2,
        6,
        0
      ],
      "state": 2
    },
    {
      "pos": [
        2,
        6,
        1
      ],
      "state": 3
    },
    {
      "pos": [
        2,
        6,
        2
      ],
      "state": 3
    },
    {
      "pos": [
        2,
        6,
        3
      ],
      "state": 3
    },
    {
      "pos": [
        2,
        6,
        4
      ],
      "state": 3
    },
    {
      "pos": [
        2,
        6,
        5
      ],
      "state": 3
    },
    {
      "pos": [
        2,
        6,
        6
      ],
      "state": 3
    },
    {
      "pos": [
        2,
        6,
        7
      ],
      "state": 3
    },
    {
      "pos": [
        2,
        6,
        8
      ],
      "state": 3
    },
    {
      "pos": [
        2,
        6,
        9
      ],
      "state": 3
    },
    {
      "pos": [
        2,
        6,
        10
      ],
      "state": 3
    },
    {
      "pos": [
        2,
        6,
        11
      ],
      "state": 3
    },
    {
      "pos": [
        2,
        6,
        12
      ],
      "state": 3
    },
    {
      "pos": [
        2,
        6,
        13
      ],
      "state": 3
    },
    {
      "pos": [
        2,
        6,
        14
      ],
      "state": 3
    },
    {
      "pos": [
        2,
        6,
        15
      ],
      "state": 3
    },
    {
      "pos": [
        2,
        6,
        16
      ],
      "state": 3
    },
    {
      "pos": [
        2,
        6,
        17
      ],
      "state": 3
    },
    {
      "pos": [
        2,
        6,
        18
      ],
      "state": 3
    },
    {
      "pos": [
        2,
        6,
        19
      ],
      "state": 3
    },
    {
      "pos": [
        2,
        6,
        20
      ],
      "state": 3
    },
    {
      "pos": [
        2,
        6,
        21
      ],
      "state": 3
    },
    {
      "pos": [
        2,
        6,
        22
      ],
      "state": 3
    },
    {
      "pos": [
        2,
        6,
        23
      ],
      "state": 2
    },
    {
      "pos": [
        2,
        7,
        0
      ],
      "state": 1
    },
    {
      "pos": [
        2,
        7,
        1
      ],
      "state": 1
    },
    {
      "pos": [
        2,
        7,
        2
      ],
      "state": 1
    },
    {
      "pos": [
        2,
        7,
        3
      ],
      "state": 1
    },
    {
      "pos": [
        2,
        7,
        4
      ],
      "state": 1
    },
    {
      "pos": [
        2,
        7,
        5
      ],
      "state": 1
    },
    {
      "pos": [
        2,
        7,
        6
      ],
      "state": 1
    },
    {
      "pos": [
        2,
        7,
        7
      ],
      "state": 1
    },
    {
      "pos": [
        2,
        7,
        8
      ],
      "state": 1
    },
    {
      "pos": [
        2,
        7,
        9
      ],
      "state": 1
    },
    {
      "pos": [
        2,
        7,
        10
      ],
      "state": 1
    },
    {
      "pos": [
        2,
        7,
        11
      ],
      "state": 1
    },
    {
      "pos": [
        2,
        7,
        12
      ],
      "state": 1
    },
    {
      "pos": [
        2,
        7,
        13
      ],
      "state": 1
    },
    {
      "pos": [
        2,
        7,
        14
      ],
      "state": 1
    },
    {
      "pos": [
        2,
        7,
        15
      ],
      "state": 1
    },
    {
      "pos": [
        2,
        7,
        16
      ],
      "state": 1
    },
    {
      "pos": [
        2,
        7,
        17
      ],
      "state": 1
    },
    {
      "pos": [
        2,
        7,
        18
      ],
      "state": 1
    },
    {
      "pos": [
        2,
        7,
        19
      ],
      "state": 1
    },
    {
      "pos": [
        2,
        7,
        20
      ],
      "state": 1
    },
    {
      "pos": [
        2,
        7,
        21
      ],
      "state": 1
    },
    {
      "pos": [
        2,
        7,
        22
      ],
      "state": 1
    },
    {
      "pos": [
        2,
        7,
        23
      ],
      "state": 1
    },
    {
      "pos": [
        3,
        0,
        0
      ],
      "state": 0
    },
    {
      "pos": [
        3,
        0,
        1
      ],
      "state": 0
    },
    {
      "pos": [
        3,
        0,
        2
      ],
      "state": 0
    },
    {
      "pos": [
        3,
        0,
        3
      ],
      "state": 0
    },
    {
      "pos": [
        3,
        0,
        4
      ],
      "state": 0
    },
    {
      "pos": [
        3,
        0,
        5
      ],
      "state": 0
    },
    {
      "pos": [
        3,
        0,
        6
      ],
      "state": 0
    },
    {
      "pos": [
        3,
        0,
        7
      ],
      "state": 0
    },
    {
      "pos": [
        3,
        0,
        8
      ],
      "state": 0
    },
    {
      "pos": [
        3,
        0,
        9
      ],
      "state": 0
    },
    {
      "pos": [
        3,
        0,
        10
      ],
      "state": 0
    },
    {
      "pos": [
        3,
        0,
        11
      ],
      "state": 0
    },
    {
      "pos": [
        3,
        0,
        12
      ],
      "state": 0
    },
    {
      "pos": [
        3,
        0,
        13
      ],
      "state": 0
    },
    {
      "pos": [
        3,
        0,
        14
      ],
      "state": 0
    },
    {
      "pos": [
        3,
        0,
        15
      ],
      "state": 0
    },
    {
      "pos": [
        3,
        0,
        16
      ],
      "state": 0
    },
    {
      "pos": [
        3,
        0,
        17
      ],
      "state": 0
    },
    {
      "pos": [
        3,
        0,
        18
      ],
      "state": 0
    },
    {
      "pos": [
        3,
        0,
        19
      ],
      "state": 0
    },
    {
      "pos": [
        3,
        0,
        20
      ],
      "state": 0
    },
    {
      "pos": [
        3,
        0,
        21
      ],
      "state": 0
    },
    {
      "pos": [
        3,
        0,
        22
      ],
      "state": 0
    },
    {
      "pos": [
        3,
        0,
        23
      ],
      "state": 0
    },
    {
      "pos": [
        3,
        1,
        0
      ],
      "state": 1
    },
    {
      "pos": [
        3,
        1,
        1
      ],
      "state": 3
    },
    {
      "pos": [
        3,
        1,
        2
      ],
      "state": 1
    },
    {
      "pos": [
        3,
        1,
        3
      ],
      "state": 3
    },
    {
      "pos": [
        3,
        1,
        4
      ],
      "state": 3
    },
    {
      "pos": [
        3,
        1,
        5
      ],
      "state": 3
    },
    {
      "pos": [
        3,
        1,
        6
      ],
      "state": 3
    },
    {
      "pos": [
        3,
        1,
        7
      ],
      "state": 3
    },
    {
      "pos": [
        3,
        1,
        8
      ],
      "state": 3
    },
    {
      "pos": [
        3,
        1,
        9
      ],
      "state": 3
    },
    {
      "pos": [
        3,
        1,
        10
      ],
      "state": 3
    },
    {
      "pos": [
        3,
        1,
        11
      ],
      "state": 3
    },
    {
      "pos": [
        3,
        1,
        12
      ],
      "state": 3
    },
    {
      "pos": [
        3,
        1,
        13
      ],
      "state": 3
    },
    {
      "pos": [
        3,
        1,
        14
      ],
      "state": 3
    },
    {
      "pos": [
        3,
        1,
        15
      ],
      "state": 3
    },
    {
      "pos": [
        3,
        1,
        16
      ],
      "state": 3
    },
    {
      "pos": [
        3,
        1,
        17
      ],
      "state": 3
    },
    {
      "pos": [
        3,
        1,
        18
      ],
      "state": 3
    },
    {
      "pos": [
        3,
        1,
        19
      ],
      "state": 3
    },
    {
      "pos": [
        3,
        1,
        20
      ],
      "state": 3
    },
    {
      "pos": [
        3,
        1,
        21
      ],
      "state": 3
    },
    {
      "pos": [
        3,
        1,
        22
      ],
      "state": 3
    },
    {
      "pos": [
        3,
        1,
        23
      ],
      "state": 1
    },
    {
      "pos": [
        3,
        2,
        0
      ],
      "state": 2
    },
    {
      "pos": [
        3,
        2,
        1
      ],
      "state": 3
    },
    {
      "pos": [
        3,
        2,
        2
      ],
      "state": 3
    },
    {
      "pos": [
        3,
        2,
        3
      ],
      "state": 3
    },
    {
      "pos": [
        3,
        2,
        4
      ],
      "state": 3
    },
    {
      "pos": [
        3,
        2,
        5
      ],
      "state": 3
    },
    {
      "pos": [
        3,
        2,
        6
      ],
      "state": 3
    },
    {
      "pos": [
        3,
        2,
        7
      ],
      "state": 3
    },
    {
      "pos": [
        3,
        2,
        8
      ],
      "state": 3
    },
    {
      "pos": [
        3,
        2,
        9
      ],
      "state": 3
    },
    {
      "pos": [
        3,
        2,
        10
      ],
      "state": 3
    },
    {
      "pos": [
        3,
        2,
        11
      ],
      "state": 3
    },
    {
      "pos": [
        3,
        2,
        12
      ],
      "state": 3
    },
    {
      "pos": [
        3,
        2,
        13
      ],
      "state": 3
    },
    {
      "pos": [
        3,
        2,
        14
      ],
      "state": 3
    },
    {
      "pos": [
        3,
        2,
        15
      ],
      "state": 3
    },
    {
      "pos": [
        3,
        2,
        16
      ],
      "state": 3
    },
    {
      "pos": [
        3,
        2,
        17
      ],
      "state": 3
    },
    {
      "pos": [
        3,
        2,
        18
      ],
      "state": 3
    },
    {
      "pos": [
        3,
        2,
        19
      ],
      "state": 3
    },
    {
      "pos": [
        3,
        2,
        20
      ],
      "state": 3
    },
    {
      "pos": [
        3,
        2,
        21
      ],
      "state": 3
    },
    {
      "pos": [
        3,
        2,
        22
      ],
      "state": 3
    },
    {
      "pos": [
        3,
        2,
        23
      ],
      "state": 2
    },
    {
      "pos": [
        3,
        3,
        0
      ],
      "state": 2
    },
    {
      "pos": [
        3,
        3,
        1
      ],
      "state": 3
    },
    {
      "pos": [
        3,
        3,
        2
      ],
      "state": 3
    },
    {
      "pos": [
        3,
        3,
        3
      ],
      "state": 3
    },
    {
      "pos": [
        3,
        3,
        4
      ],
      "state": 3
    },
    {
      "pos": [
        3,
        3,
        5
      ],
      "state": 3
    },
    {
      "pos": [
        3,
        3,
        6
      ],
      "state": 3
    },
    {
      "pos": [
        3,
        3,
        7
      ],
      "state": 3
    },
    {
      "pos": [
        3,
        3,
        8
      ],
      "state": 3
    },
    {
      "pos": [
        3,
        3,
        9
      ],
      "state": 3
    },
    {
      "pos": [
        3,
        3,
        10
      ],
      "state": 3
    },
    {
      "pos": [
        3,
        3,
        11
      ],
      "state": 3
    },
    {
      "pos": [
        3,
        3,
        12
      ],
      "state": 3
    },
    {
      "pos": [
        3,
        3,
        13
      ],
      "state": 3
    },
    {
      "pos": [
        3,
        3,
        14
      ],
      "state": 3
    },
    {
      "pos": [
        3,
        3,
        15
      ],
      "state": 3
    },
    {
      "pos": [
        3,
        3,
        16
      ],
      "state": 3
    },
    {
      "pos": [
        3,
        3,
        17
      ],
      "state": 3
    },
    {
      "pos": [
        3,
        3,
        18
      ],
      "state": 3
    },
    {
      "pos": [
        3,
        3,
        19
      ],
      "state": 3
    },
    {
      "pos": [
        3,
        3,
        20
      ],
      "state": 3
    },
    {
      "pos": [
        3,
        3,
        21
      ],
      "state": 3
    },
    {
      "pos": [
        3,
        3,
        22
      ],
      "state": 3
    },
    {
      "pos": [
        3,
        3,
        23
      ],
      "state": 2
    },
    {
      "pos": [
        3,
        4,
        0
      ],
      "state": 2
    },
    {
      "pos": [
        3,
        4,
        1
      ],
      "state": 3
    },
    {
      "pos": [
        3,
        4,
        2
      ],
      "state": 3
    },
    {
      "pos": [
        3,
        4,
        3
      ],
      "state": 3
    },
    {
      "pos": [
        3,
        4,
        4
      ],
      "state": 3
    },
    {
      "pos": [
        3,
        4,
        5
      ],
      "state": 3
    },
    {
      "pos": [
        3,
        4,
        6
      ],
      "state": 3
    },
    {
      "pos": [
        3,
        4,
        7
      ],
      "state": 3
    },
    {
      "pos": [
        3,
        4,
        8
      ],
      "state": 3
    },
    {
      "pos": [
        3,
        4,
        9
      ],
      "state": 3
    },
    {
      "pos": [
        3,
        4,
        10
      ],
      "state": 3
    },
    {
      "pos": [
        3,
        4,
        11
      ],
      "state": 3
    },
    {
      "pos": [
        3,
        4,
        12
      ],
      "state": 3
    },
    {
      "pos": [
        3,
        4,
        13
      ],
      "state": 3
    },
    {
      "pos": [
        3,
        4,
        14
      ],
      "state": 3
    },
    {
      "pos": [
        3,
        4,
        15
      ],
      "state": 3
    },
    {
      "pos": [
        3,
        4,
        16
      ],
      "state": 3
    },
    {
      "pos": [
        3,
        4,
        17
      ],
      "state": 3
    },
    {
      "pos": [
        3,
        4,
        18
      ],
      "state": 3
    },
    {
      "pos": [
        3,
        4,
        19
      ],
      "state": 3
    },
    {
      "pos": [
        3,
        4,
        20
      ],
      "state": 3
    },
    {
      "pos": [
        3,
        4,
        21
      ],
      "state": 3
    },
    {
      "pos": [
        3,
        4,
        22
      ],
      "state": 3
    },
    {
      "pos": [
        3,
        4,
        23
      ],
      "state": 2
    },
    {
      "pos": [
        3,
        5,
        0
      ],
      "state": 2
    },
    {
      "pos": [
        3,
        5,
        1
      ],
      "state": 3
    },
    {
      "pos": [
        3,
        5,
        2
      ],
      "state": 3
    },
    {
      "pos": [
        3,
        5,
        3
      ],
      "state": 3
    },
    {
      "pos": [
        3,
        5,
        4
      ],
      "state": 3
    },
    {
      "pos": [
        3,
        5,
        5
      ],
      "state": 3
    },
    {
      "pos": [
        3,
        5,
        6
      ],
      "state": 3
    },
    {
      "pos": [
        3,
        5,
        7
      ],
      "state": 3
    },
    {
      "pos": [
        3,
        5,
        8
      ],
      "state": 3
    },
    {
      "pos": [
        3,
        5,
        9
      ],
      "state": 3
    },
    {
      "pos": [
        3,
        5,
        10
      ],
      "state": 3
    },
    {
      "pos": [
        3,
        5,
        11
      ],
      "state": 3
    },
    {
      "pos": [
        3,
        5,
        12
      ],
      "state": 3
    },
    {
      "pos": [
        3,
        5,
        13
      ],
      "state": 3
    },
    {
      "pos": [
        3,
        5,
        14
      ],
      "state": 3
    },
    {
      "pos": [
        3,
        5,
        15
      ],
      "state": 3
    },
    {
      "pos": [
        3,
        5,
        16
      ],
      "state": 3
    },
    {
      "pos": [
        3,
        5,
        17
      ],
      "state": 3
    },
    {
      "pos": [
        3,
        5,
        18
      ],
      "state": 3
    },
    {
      "pos": [
        3,
        5,
        19
      ],
      "state": 3
    },
    {
      "pos": [
        3,
        5,
        20
      ],
      "state": 3
    },
    {
      "pos": [
        3,
        5,
        21
      ],
      "state": 3
    },
    {
      "pos": [
        3,
        5,
        22
      ],
      "state": 3
    },
    {
      "pos": [
        3,
        5,
        23
      ],
      "state": 2
    },
    {
      "pos": [
        3,
        6,
        0
      ],
      "state": 2
    },
    {
      "pos": [
        3,
        6,
        1
      ],
      "state": 3
    },
    {
      "pos": [
        3,
        6,
        2
      ],
      "state": 3
    },
    {
      "pos": [
        3,
        6,
        3
      ],
      "state": 3
    },
    {
      "pos": [
        3,
        6,
        4
      ],
      "state": 3
    },
    {
      "pos": [
        3,
        6,
        5
      ],
      "state": 3
    },
    {
      "pos": [
        3,
        6,
        6
      ],
      "state": 3
    },
    {
      "pos": [
        3,
        6,
        7
      ],
      "state": 3
    },
    {
      "pos": [
        3,
        6,
        8
      ],
      "state": 3
    },
    {
      "pos": [
        3,
        6,
        9
      ],
      "state": 3
    },
    {
      "pos": [
        3,
        6,
        10
      ],
      "state": 3
    },
    {
      "pos": [
        3,
        6,
        11
      ],
      "state": 3
    },
    {
      "pos": [
        3,
        6,
        12
      ],
      "state": 3
    },
    {
      "pos": [
        3,
        6,
        13
      ],
      "state": 3
    },
    {
      "pos": [
        3,
        6,
        14
      ],
      "state": 3
    },
    {
      "pos": [
        3,
        6,
        15
      ],
      "state": 3
    },
    {
      "pos": [
        3,
        6,
        16
      ],
      "state": 3
    },
    {
      "pos": [
        3,
        6,
        17
      ],
      "state": 3
    },
    {
      "pos": [
        3,
        6,
        18
      ],
      "state": 3
    },
    {
      "pos": [
        3,
        6,
        19
      ],
      "state": 3
    },
    {
      "pos": [
        3,
        6,
        20
      ],
      "state": 3
    },
    {
      "pos": [
        3,
        6,
        21
      ],
      "state": 3
    },
    {
      "pos": [
        3,
        6,
        22
      ],
      "state": 3
    },
    {
      "pos": [
        3,
        6,
        23
      ],
      "state": 2
    },
    {
      "pos": [
        3,
        7,
        0
      ],
      "state": 1
    },
    {
      "pos": [
        3,
        7,
        1
      ],
      "state": 1
    },
    {
      "pos": [
        3,
        7,
        2
      ],
      "state": 1
    },
    {
      "pos": [
        3,
        7,
        3
      ],
      "state": 1
    },
    {
      "pos": [
        3,
        7,
        4
      ],
      "state": 1
    },
    {
      "pos": [
        3,
        7,
        5
      ],
      "state": 1
    },
    {
      "pos": [
        3,
        7,
        6
      ],
      "state": 1
    },
    {
      "pos": [
        3,
        7,
        7
      ],
      "state": 1
    },
    {
      "pos": [
        3,
        7,
        8
      ],
      "state": 1
    },
    {
      "pos": [
        3,
        7,
        9
      ],
      "state": 1
    },
    {
      "pos": [
        3,
        7,
        10
      ],
      "state": 1
    },
    {
      "pos": [
        3,
        7,
        11
      ],
      "state": 1
    },
    {
      "pos": [
        3,
        7,
        12
      ],
      "state": 1
    },
    {
      "pos": [
        3,
        7,
        13
      ],
      "state": 1
    },
    {
      "pos": [
        3,
        7,
        14
      ],
      "state": 1
    },
    {
      "pos": [
        3,
        7,
        15
      ],
      "state": 1
    },
    {
      "pos": [
        3,
        7,
        16
      ],
      "state": 1
    },
    {
      "pos": [
        3,
        7,
        17
      ],
      "state": 1
    },
    {
      "pos": [
        3,
        7,
        18
      ],
      "state": 1
    },
    {
      "pos": [
        3,
        7,
        19
      ],
      "state": 1
    },
    {
      "pos": [
        3,
        7,
        20
      ],
      "state": 1
    },
    {
      "pos": [
        3,
        7,
        21
      ],
      "state": 1
    },
    {
      "pos": [
        3,
        7,
        22
      ],
      "state": 1
    },
    {
      "pos": [
        3,
        7,
        23
      ],
      "state": 1
    },
    {
      "pos": [
        4,
        0,
        0
      ],
      "state": 0
    },
    {
      "pos": [
        4,
        0,
        1
      ],
      "state": 0
    },
    {
      "pos": [
        4,
        0,
        2
      ],
      "state": 0
    },
    {
      "pos": [
        4,
        0,
        3
      ],
      "state": 0
    },
    {
      "pos": [
        4,
        0,
        4
      ],
      "state": 0
    },
    {
      "pos": [
        4,
        0,
        5
      ],
      "state": 0
    },
    {
      "pos": [
        4,
        0,
        6
      ],
      "state": 0
    },
    {
      "pos": [
        4,
        0,
        7
      ],
      "state": 0
    },
    {
      "pos": [
        4,
        0,
        8
      ],
      "state": 0
    },
    {
      "pos": [
        4,
        0,
        9
      ],
      "state": 0
    },
    {
      "pos": [
        4,
        0,
        10
      ],
      "state": 0
    },
    {
      "pos": [
        4,
        0,
        11
      ],
      "state": 0
    },
    {
      "pos": [
        4,
        0,
        12
      ],
      "state": 0
    },
    {
      "pos": [
        4,
        0,
        13
      ],
      "state": 0
    },
    {
      "pos": [
        4,
        0,
        14
      ],
      "state": 0
    },
    {
      "pos": [
        4,
        0,
        15
      ],
      "state": 0
    },
    {
      "pos": [
        4,
        0,
        16
      ],
      "state": 0
    },
    {
      "pos": [
        4,
        0,
        17
      ],
      "state": 0
    },
    {
      "pos": [
        4,
        0,
        18
      ],
      "state": 0
    },
    {
      "pos": [
        4,
        0,
        19
      ],
      "state": 0
    },
    {
      "pos": [
        4,
        0,
        20
      ],
      "state": 0
    },
    {
      "pos": [
        4,
        0,
        21
      ],
      "state": 0
    },
    {
      "pos": [
        4,
        0,
        22
      ],
      "state": 0
    },
    {
      "pos": [
        4,
        0,
        23
      ],
      "state": 0
    },
    {
      "pos": [
        4,
        1,
        0
      ],
      "state": 1
    },
    {
      "pos": [
        4,
        1,
        1
      ],
      "state": 3
    },
    {
      "pos": [
        4,
        1,
        2
      ],
      "state": 1
    },
    {
      "pos": [
        4,
        1,
        3
      ],
      "state": 3
    },
    {
      "pos": [
        4,
        1,
        4
      ],
      "state": 3
    },
    {
      "pos": [
        4,
        1,
        5
      ],
      "state": 3
    },
    {
      "pos": [
        4,
        1,
        6
      ],
      "state": 3
    },
    {
      "pos": [
        4,
        1,
        7
      ],
      "state": 3
    },
    {
      "pos": [
        4,
        1,
        8
      ],
      "state": 3
    },
    {
      "pos": [
        4,
        1,
        9
      ],
      "state": 3
    },
    {
      "pos": [
        4,
        1,
        10
      ],
      "state": 3
    },
    {
      "pos": [
        4,
        1,
        11
      ],
      "state": 3
    },
    {
      "pos": [
        4,
        1,
        12
      ],
      "state": 3
    },
    {
      "pos": [
        4,
        1,
        13
      ],
      "state": 3
    },
    {
      "pos": [
        4,
        1,
        14
      ],
      "state": 3
    },
    {
      "pos": [
        4,
        1,
        15
      ],
      "state": 3
    },
    {
      "pos": [
        4,
        1,
        16
      ],
      "state": 3
    },
    {
      "pos": [
        4,
        1,
        17
      ],
      "state": 3
    },
    {
      "pos": [
        4,
        1,
        18
      ],
      "state": 3
    },
    {
      "pos": [
        4,
        1,
        19
      ],
      "state": 3
    },
    {
      "pos": [
        4,
        1,
        20
      ],
      "state": 3
    },
    {
      "pos": [
        4,
        1,
        21
      ],
      "state": 3
    },
    {
      "pos": [
        4,
        1,
        22
      ],
      "state": 3
    },
    {
      "pos": [
        4,
        1,
        23
      ],
      "state": 1
    },
    {
      "pos": [
        4,
        2,
        0
      ],
      "state": 2
    },
    {
      "pos": [
        4,
        2,
        1
      ],
      "state": 3
    },
    {
      "pos": [
        4,
        2,
        2
      ],
      "state": 7
    },
    {
      "pos": [
        4,
        2,
        3
      ],
      "state": 3
    },
    {
      "pos": [
        4,
        2,
        4
      ],
      "state": 3
    },
    {
      "pos": [
        4,
        2,
        5
      ],
      "state": 3
    },
    {
      "pos": [
        4,
        2,
        6
      ],
      "state": 3
    },
    {
      "pos": [
        4,
        2,
        7
      ],
      "state": 3
    },
    {
      "pos": [
        4,
        2,
        8
      ],
      "state": 3
    },
    {
      "pos": [
        4,
        2,
        9
      ],
      "state": 3
    },
    {
      "pos": [
        4,
        2,
        10
      ],
      "state": 3
    },
    {
      "pos": [
        4,
        2,
        11
      ],
      "state": 3
    },
    {
      "pos": [
        4,
        2,
        12
      ],
      "state": 3
    },
    {
      "pos": [
        4,
        2,
        13
      ],
      "state": 3
    },
    {
      "pos": [
        4,
        2,
        14
      ],
      "state": 3
    },
    {
      "pos": [
        4,
        2,
        15
      ],
      "state": 3
    },
    {
      "pos": [
        4,
        2,
        16
      ],
      "state": 3
    },
    {
      "pos": [
        4,
        2,
        17
      ],
      "state": 3
    },
    {
      "pos": [
        4,
        2,
        18
      ],
      "state": 3
    },
    {
      "pos": [
        4,
        2,
        19
      ],
      "state": 3
    },
    {
      "pos": [
        4,
        2,
        20
      ],
      "state": 3
    },
    {
      "pos": [
        4,
        2,
        21
      ],
      "state": 3
    },
    {
      "pos": [
        4,
        2,
        22
      ],
      "state": 3
    },
    {
      "pos": [
        4,
        2,
        23
      ],
      "state": 2
    },
    {
      "pos": [
        4,
        3,
        0
      ],
      "state": 8
    },
    {
      "pos": [
        4,
        3,
        1
      ],
      "state": 3
    },
    {
      "pos": [
        4,
        3,
        2
      ],
      "state": 8
    },
    {
      "pos": [
        4,
        3,
        3
      ],
      "state": 3
    },
    {
      "pos": [
        4,
        3,
        4
      ],
      "state": 3
    },
    {
      "pos": [
        4,
        3,
        5
      ],
      "state": 3
    },
    {
      "pos": [
        4,
        3,
        6
      ],
      "state": 3
    },
    {
      "pos": [
        4,
        3,
        7
      ],
      "state": 3
    },
    {
      "pos": [
        4,
        3,
        8
      ],
      "state": 3
    },
    {
      "pos": [
        4,
        3,
        9
      ],
      "state": 3
    },
    {
      "pos": [
        4,
        3,
        10
      ],
      "state": 3
    },
    {
      "pos": [
        4,
        3,
        11
      ],
      "state": 3
    },
    {
      "pos": [
        4,
        3,
        12
      ],
      "state": 3
    },
    {
      "pos": [
        4,
        3,
        13
      ],
      "state": 3
    },
    {
      "pos": [
        4,
        3,
        14
      ],
      "state": 3
    },
    {
      "pos": [
        4,
        3,
        15
      ],
      "state": 3
    },
    {
      "pos": [
        4,
        3,
        16
      ],
      "state": 3
    },
    {
      "pos": [
        4,
        3,
        17
      ],
      "state": 3
    },
    {
      "pos": [
        4,
        3,
        18
      ],
      "state": 3
    },
    {
      "pos": [
        4,
        3,
        19
      ],
      "state": 3
    },
    {
      "pos": [
        4,
        3,
        20
      ],
      "state": 3
    },
    {
      "pos": [
        4,
        3,
        21
      ],
      "state": 3
    },
    {
      "pos": [
        4,
        3,
        22
      ],
      "state": 3
    },
    {
      "pos": [
        4,
        3,
        23
      ],
      "state": 2
    },
    {
      "pos": [
        4,
        4,
        0
      ],
      "state": 8
    },
    {
      "pos": [
        4,
        4,
        1
      ],
      "state": 3
    },
    {
      "pos": [
        4,
        4,
        2
      ],
      "state": 3
    },
    {
      "pos": [
        4,
        4,
        3
      ],
      "state": 3
    },
    {
      "pos": [
        4,
        4,
        4
      ],
      "state": 3
    },
    {
      "pos": [
        4,
        4,
        5
      ],
      "state": 3
    },
    {
      "pos": [
        4,
        4,
        6
      ],
      "state": 3
    },
    {
      "pos": [
        4,
        4,
        7
      ],
      "state": 3
    },
    {
      "pos": [
        4,
        4,
        8
      ],
      "state": 3
    },
    {
      "pos": [
        4,
        4,
        9
      ],
      "state": 3
    },
    {
      "pos": [
        4,
        4,
        10
      ],
      "state": 3
    },
    {
      "pos": [
        4,
        4,
        11
      ],
      "state": 3
    },
    {
      "pos": [
        4,
        4,
        12
      ],
      "state": 3
    },
    {
      "pos": [
        4,
        4,
        13
      ],
      "state": 3
    },
    {
      "pos": [
        4,
        4,
        14
      ],
      "state": 3
    },
    {
      "pos": [
        4,
        4,
        15
      ],
      "state": 3
    },
    {
      "pos": [
        4,
        4,
        16
      ],
      "state": 3
    },
    {
      "pos": [
        4,
        4,
        17
      ],
      "state": 3
    },
    {
      "pos": [
        4,
        4,
        18
      ],
      "state": 3
    },
    {
      "pos": [
        4,
        4,
        19
      ],
      "state": 3
    },
    {
      "pos": [
        4,
        4,
        20
      ],
      "state": 3
    },
    {
      "pos": [
        4,
        4,
        21
      ],
      "state": 3
    },
    {
      "pos": [
        4,
        4,
        22
      ],
      "state": 3
    },
    {
      "pos": [
        4,
        4,
        23
      ],
      "state": 2
    },
    {
      "pos": [
        4,
        5,
        0
      ],
      "state": 2
    },
    {
      "pos": [
        4,
        5,
        1
      ],
      "state": 3
    },
    {
      "pos": [
        4,
        5,
        2
      ],
      "state": 3
    },
    {
      "pos": [
        4,
        5,
        3
      ],
      "state": 3
    },
    {
      "pos": [
        4,
        5,
        4
      ],
      "state": 3
    },
    {
      "pos": [
        4,
        5,
        5
      ],
      "state": 3
    },
    {
      "pos": [
        4,
        5,
        6
      ],
      "state": 3
    },
    {
      "pos": [
        4,
        5,
        7
      ],
      "state": 3
    },
    {
      "pos": [
        4,
        5,
        8
      ],
      "state": 3
    },
    {
      "pos": [
        4,
        5,
        9
      ],
      "state": 3
    },
    {
      "pos": [
        4,
        5,
        10
      ],
      "state": 3
    },
    {
      "pos": [
        4,
        5,
        11
      ],
      "state": 3
    },
    {
      "pos": [
        4,
        5,
        12
      ],
      "state": 3
    },
    {
      "pos": [
        4,
        5,
        13
      ],
      "state": 3
    },
    {
      "pos": [
        4,
        5,
        14
      ],
      "state": 3
    },
    {
      "pos": [
        4,
        5,
        15
      ],
      "state": 3
    },
    {
      "pos": [
        4,
        5,
        16
      ],
      "state": 3
    },
    {
      "pos": [
        4,
        5,
        17
      ],
      "state": 3
    },
    {
      "pos": [
        4,
        5,
        18
      ],
      "state": 3
    },
    {
      "pos": [
        4,
        5,
        19
      ],
      "state": 3
    },
    {
      "pos": [
        4,
        5,
        20
      ],
      "state": 3
    },
    {
      "pos": [
        4,
        5,
        21
      ],
      "state": 3
    },
    {
      "pos": [
        4,
        5,
        22
      ],
      "state": 3
    },
    {
      "pos": [
        4,
        5,
        23
      ],
      "state": 2
    },
    {
      "pos": [
        4,
        6,
        0
      ],
      "state": 2
    },
    {
      "pos": [
        4,
        6,
        1
      ],
      "state": 3
    },
    {
      "pos": [
        4,
        6,
        2
      ],
      "state": 3
    },
    {
      "pos": [
        4,
        6,
        3
      ],
      "state": 3
    },
    {
      "pos": [
        4,
        6,
        4
      ],
      "state": 3
    },
    {
      "pos": [
        4,
        6,
        5
      ],
      "state": 3
    },
    {
      "pos": [
        4,
        6,
        6
      ],
      "state": 3
    },
    {
      "pos": [
        4,
        6,
        7
      ],
      "state": 3
    },
    {
      "pos": [
        4,
        6,
        8
      ],
      "state": 3
    },
    {
      "pos": [
        4,
        6,
        9
      ],
      "state": 3
    },
    {
      "pos": [
        4,
        6,
        10
      ],
      "state": 3
    },
    {
      "pos": [
        4,
        6,
        11
      ],
      "state": 3
    },
    {
      "pos": [
        4,
        6,
        12
      ],
      "state": 3
    },
    {
      "pos": [
        4,
        6,
        13
      ],
      "state": 3
    },
    {
      "pos": [
        4,
        6,
        14
      ],
      "state": 3
    },
    {
      "pos": [
        4,
        6,
        15
      ],
      "state": 3
    },
    {
      "pos": [
        4,
        6,
        16
      ],
      "state": 3
    },
    {
      "pos": [
        4,
        6,
        17
      ],
      "state": 3
    },
    {
      "pos": [
        4,
        6,
        18
      ],
      "state": 3
    },
    {
      "pos": [
        4,
        6,
        19
      ],
      "state": 3
    },
    {
      "pos": [
        4,
        6,
        20
      ],
      "state": 3
    },
    {
      "pos": [
        4,
        6,
        21
      ],
      "state": 3
    },
    {
      "pos": [
        4,
        6,
        22
      ],
      "state": 3
    },
    {
      "pos": [
        4,
        6,
        23
      ],
      "state": 2
    },
    {
      "pos": [
        4,
        7,
        0
      ],
      "state": 1
    },
    {
      "pos": [
        4,
        7,
        1
      ],
      "state": 1
    },
    {
      "pos": [
        4,
        7,
        2
      ],
      "state": 1
    },
    {
      "pos": [
        4,
        7,
        3
      ],
      "state": 1
    },
    {
      "pos": [
        4,
        7,
        4
      ],
      "state": 9
    },
    {
      "pos": [
        4,
        7,
        5
      ],
      "state": 1
    },
    {
      "pos": [
        4,
        7,
        6
      ],
      "state": 1
    },
    {
      "pos": [
        4,
        7,
        7
      ],
      "state": 1
    },
    {
      "pos": [
        4,
        7,
        8
      ],
      "state": 1
    },
    {
      "pos": [
        4,
        7,
        9
      ],
      "state": 1
    },
    {
      "pos": [
        4,
        7,
        10
      ],
      "state": 9
    },
    {
      "pos": [
        4,
        7,
        11
      ],
      "state": 1
    },
    {
      "pos": [
        4,
        7,
        12
      ],
      "state": 1
    },
    {
      "pos": [
        4,
        7,
        13
      ],
      "state": 1
    },
    {
      "pos": [
        4,
        7,
        14
      ],
      "state": 1
    },
    {
      "pos": [
        4,
        7,
        15
      ],
      "state": 1
    },
    {
      "pos": [
        4,
        7,
        16
      ],
      "state": 9
    },
    {
      "pos": [
        4,
        7,
        17
      ],
      "state": 1
    },
    {
      "pos": [
        4,
        7,
        18
      ],
      "state": 1
    },
    {
      "pos": [
        4,
        7,
        19
      ],
      "state": 1
    },
    {
      "pos": [
        4,
        7,
        20
      ],
      "state": 1
    },
    {
      "pos": [
        4,
        7,
        21
      ],
      "state": 1
    },
    {
      "pos": [
        4,
        7,
        22
      ],
      "state": 1
    },
    {
      "pos": [
        4,
        7,
        23
      ],
      "state": 1
    },
    {
      "pos": [
        5,
        0,
        0
      ],
      "state": 0
    },
    {
      "pos": [
        5,
        0,
        1
      ],
      "state": 0
    },
    {
      "pos": [
        5,
        0,
        2
      ],
      "state": 0
    },
    {
      "pos": [
        5,
        0,
        3
      ],
      "state": 0
    },
    {
      "pos": [
        5,
        0,
        4
      ],
      "state": 0
    },
    {
      "pos": [
        5,
        0,
        5
      ],
      "state": 0
    },
    {
      "pos": [
        5,
        0,
        6
      ],
      "state": 0
    },
    {
      "pos": [
        5,
        0,
        7
      ],
      "state": 0
    },
    {
      "pos": [
        5,
        0,
        8
      ],
      "state": 0
    },
    {
      "pos": [
        5,
        0,
        9
      ],
      "state": 0
    },
    {
      "pos": [
        5,
        0,
        10
      ],
      "state": 0
    },
    {
      "pos": [
        5,
        0,
        11
      ],
      "state": 0
    },
    {
      "pos": [
        5,
        0,
        12
      ],
      "state": 0
    },
    {
      "pos": [
        5,
        0,
        13
      ],
      "state": 0
    },
    {
      "pos": [
        5,
        0,
        14
      ],
      "state": 0
    },
    {
      "pos": [
        5,
        0,
        15
      ],
      "state": 0
    },
    {
      "pos": [
        5,
        0,
        16
      ],
      "state": 0
    },
    {
      "pos": [
        5,
        0,
        17
      ],
      "state": 0
    },
    {
      "pos": [
        5,
        0,
        18
      ],
      "state": 0
    },
    {
      "pos": [
        5,
        0,
        19
      ],
      "state": 0
    },
    {
      "pos": [
        5,
        0,
        20
      ],
      "state": 0
    },
    {
      "pos": [
        5,
        0,
        21
      ],
      "state": 0
    },
    {
      "pos": [
        5,
        0,
        22
      ],
      "state": 0
    },
    {
      "pos": [
        5,
        0,
        23
      ],
      "state": 0
    },
    {
      "pos": [
        5,
        1,
        0
      ],
      "state": 1
    },
    {
      "pos": [
        5,
        1,
        1
      ],
      "state": 3
    },
    {
      "pos": [
        5,
        1,
        2
      ],
      "state": 1
    },
    {
      "pos": [
        5,
        1,
        3
      ],
      "state": 3
    },
    {
      "pos": [
        5,
        1,
        4
      ],
      "state": 3
    },
    {
      "pos": [
        5,
        1,
        5
      ],
      "state": 3
    },
    {
      "pos": [
        5,
        1,
        6
      ],
      "state": 3
    },
    {
      "pos": [
        5,
        1,
        7
      ],
      "state": 3
    },
    {
      "pos": [
        5,
        1,
        8
      ],
      "state": 3
    },
    {
      "pos": [
        5,
        1,
        9
      ],
      "state": 3
    },
    {
      "pos": [
        5,
        1,
        10
      ],
      "state": 3
    },
    {
      "pos": [
        5,
        1,
        11
      ],
      "state": 3
    },
    {
      "pos": [
        5,
        1,
        12
      ],
      "state": 3
    },
    {
      "pos": [
        5,
        1,
        13
      ],
      "state": 3
    },
    {
      "pos": [
        5,
        1,
        14
      ],
      "state": 3
    },
    {
      "pos": [
        5,
        1,
        15
      ],
      "state": 3
    },
    {
      "pos": [
        5,
        1,
        16
      ],
      "state": 3
    },
    {
      "pos": [
        5,
        1,
        17
      ],
      "state": 3
    },
    {
      "pos": [
        5,
        1,
        18
      ],
      "state": 3
    },
    {
      "pos": [
        5,
        1,
        19
      ],
      "state": 3
    },
    {
      "pos": [
        5,
        1,
        20
      ],
      "state": 3
    },
    {
      "pos": [
        5,
        1,
        21
      ],
      "state": 3
    },
    {
      "pos": [
        5,
        1,
        22
      ],
      "state": 3
    },
    {
      "pos": [
        5,
        1,
        23
      ],
      "state": 1
    },
    {
      "pos": [
        5,
        2,
        0
      ],
      "state": 2
    },
    {
      "pos": [
        5,
        2,
        1
      ],
      "state": 3
    },
    {
      "pos": [
        5,
        2,
        2
      ],
      "state": 3
    },
    {
      "pos": [
        5,
        2,
        3
      ],
      "state": 3
    },
    {
      "pos": [
        5,
        2,
        4
      ],
      "state": 3
    },
    {
      "pos": [
        5,
        2,
        5
      ],
      "state": 3
    },
    {
      "pos": [
        5,
        2,
        6
      ],
      "state": 3
    },
    {
      "pos": [
        5,
        2,
        7
      ],
      "state": 3
    },
    {
      "pos": [
        5,
        2,
        8
      ],
      "state": 3
    },
    {
      "pos": [
        5,
        2,
        9
      ],
      "state": 3
    },
    {
      "pos": [
        5,
        2,
        10
      ],
      "state": 3
    },
    {
      "pos": [
        5,
        2,
        11
      ],
      "state": 3
    },
    {
      "pos": [
        5,
        2,
        12
      ],
      "state": 3
    },
    {
      "pos": [
        5,
        2,
        13
      ],
      "state": 3
    },
    {
      "pos": [
        5,
        2,
        14
      ],
      "state": 3
    },
    {
      "pos": [
        5,
        2,
        15
      ],
      "state": 3
    },
    {
      "pos": [
        5,
        2,
        16
      ],
      "state": 3
    },
    {
      "pos": [
        5,
        2,
        17
      ],
      "state": 3
    },
    {
      "pos": [
        5,
        2,
        18
      ],
      "state": 3
    },
    {
      "pos": [
        5,
        2,
        19
      ],
      "state": 3
    },
    {
      "pos": [
        5,
        2,
        20
      ],
      "state": 3
    },
    {
      "pos": [
        5,
        2,
        21
      ],
      "state": 3
    },
    {
      "pos": [
        5,
        2,
        22
      ],
      "state": 3
    },
    {
      "pos": [
        5,
        2,
        23
      ],
      "state": 2
    },
    {
      "pos": [
        5,
        3,
        0
      ],
      "state": 8
    },
    {
      "pos": [
        5,
        3,
        1
      ],
      "state": 3
    },
    {
      "pos": [
        5,
        3,
        2
      ],
      "state": 3
    },
    {
      "pos": [
        5,
        3,
        3
      ],
      "state": 3
    },
    {
      "pos": [
        5,
        3,
        4
      ],
      "state": 3
    },
    {
      "pos": [
        5,
        3,
        5
      ],
      "state": 3
    },
    {
      "pos": [
        5,
        3,
        6
      ],
      "state": 3
    },
    {
      "pos": [
        5,
        3,
        7
      ],
      "state": 3
    },
    {
      "pos": [
        5,
        3,
        8
      ],
      "state": 3
    },
    {
      "pos": [
        5,
        3,
        9
      ],
      "state": 3
    },
    {
      "pos": [
        5,
        3,
        10
      ],
      "state": 3
    },
    {
      "pos": [
        5,
        3,
        11
      ],
      "state": 3
    },
    {
      "pos": [
        5,
        3,
        12
      ],
      "state": 3
    },
    {
      "pos": [
        5,
        3,
        13
      ],
      "state": 3
    },
    {
      "pos": [
        5,
        3,
        14
      ],
      "state": 3
    },
    {
      "pos": [
        5,
        3,
        15
      ],
      "state": 3
    },
    {
      "pos": [
        5,
        3,
        16
      ],
      "state": 3
    },
    {
      "pos": [
        5,
        3,
        17
      ],
      "state": 3
    },
    {
      "pos": [
        5,
        3,
        18
      ],
      "state": 3
    },
    {
      "pos": [
        5,
        3,
        19
      ],
      "state": 3
    },
    {
      "pos": [
        5,
        3,
        20
      ],
      "state": 3
    },
    {
      "pos": [
        5,
        3,
        21
      ],
      "state": 3
    },
    {
      "pos": [
        5,
        3,
        22
      ],
      "state": 3
    },
    {
      "pos": [
        5,
        3,
        23
      ],
      "state": 2
    },
    {
      "pos": [
        5,
        4,
        0
      ],
      "state": 8
    },
    {
      "pos": [
        5,
        4,
        1
      ],
      "state": 3
    },
    {
      "pos": [
        5,
        4,
        2
      ],
      "state": 3
    },
    {
      "pos": [
        5,
        4,
        3
      ],
      "state": 3
    },
    {
      "pos": [
        5,
        4,
        4
      ],
      "state": 3
    },
    {
      "pos": [
        5,
        4,
        5
      ],
      "state": 3
    },
    {
      "pos": [
        5,
        4,
        6
      ],
      "state": 3
    },
    {
      "pos": [
        5,
        4,
        7
      ],
      "state": 3
    },
    {
      "pos": [
        5,
        4,
        8
      ],
      "state": 3
    },
    {
      "pos": [
        5,
        4,
        9
      ],
      "state": 3
    },
    {
      "pos": [
        5,
        4,
        10
      ],
      "state": 3
    },
    {
      "pos": [
        5,
        4,
        11
      ],
      "state": 3
    },
    {
      "pos": [
        5,
        4,
        12
      ],
      "state": 3
    },
    {
      "pos": [
        5,
        4,
        13
      ],
      "state": 3
    },
    {
      "pos": [
        5,
        4,
        14
      ],
      "state": 3
    },
    {
      "pos": [
        5,
        4,
        15
      ],
      "state": 3
    },
    {
      "pos": [
        5,
        4,
        16
      ],
      "state": 3
    },
    {
      "pos": [
        5,
        4,
        17
      ],
      "state": 3
    },
    {
      "pos": [
        5,
        4,
        18
      ],
      "state": 3
    },
    {
      "pos": [
        5,
        4,
        19
      ],
      "state": 3
    },
    {
      "pos": [
        5,
        4,
        20
      ],
      "state": 3
    },
    {
      "pos": [
        5,
        4,
        21
      ],
      "state": 3
    },
    {
      "pos": [
        5,
        4,
        22
      ],
      "state": 3
    },
    {
      "pos": [
        5,
        4,
        23
      ],
      "state": 2
    },
    {
      "pos": [
        5,
        5,
        0
      ],
      "state": 2
    },
    {
      "pos": [
        5,
        5,
        1
      ],
      "state": 3
    },
    {
      "pos": [
        5,
        5,
        2
      ],
      "state": 3
    },
    {
      "pos": [
        5,
        5,
        3
      ],
      "state": 3
    },
    {
      "pos": [
        5,
        5,
        4
      ],
      "state": 3
    },
    {
      "pos": [
        5,
        5,
        5
      ],
      "state": 3
    },
    {
      "pos": [
        5,
        5,
        6
      ],
      "state": 3
    },
    {
      "pos": [
        5,
        5,
        7
      ],
      "state": 3
    },
    {
      "pos": [
        5,
        5,
        8
      ],
      "state": 3
    },
    {
      "pos": [
        5,
        5,
        9
      ],
      "state": 3
    },
    {
      "pos": [
        5,
        5,
        10
      ],
      "state": 3
    },
    {
      "pos": [
        5,
        5,
        11
      ],
      "state": 3
    },
    {
      "pos": [
        5,
        5,
        12
      ],
      "state": 3
    },
    {
      "pos": [
        5,
        5,
        13
      ],
      "state": 3
    },
    {
      "pos": [
        5,
        5,
        14
      ],
      "state": 3
    },
    {
      "pos": [
        5,
        5,
        15
      ],
      "state": 3
    },
    {
      "pos": [
        5,
        5,
        16
      ],
      "state": 3
    },
    {
      "pos": [
        5,
        5,
        17
      ],
      "state": 3
    },
    {
      "pos": [
        5,
        5,
        18
      ],
      "state": 3
    },
    {
      "pos": [
        5,
        5,
        19
      ],
      "state": 3
    },
    {
      "pos": [
        5,
        5,
        20
      ],
      "state": 3
    },
    {
      "pos": [
        5,
        5,
        21
      ],
      "state": 3
    },
    {
      "pos": [
        5,
        5,
        22
      ],
      "state": 3
    },
    {
      "pos": [
        5,
        5,
        23
      ],
      "state": 2
    },
    {
      "pos": [
        5,
        6,
        0
      ],
      "state": 2
    },
    {
      "pos": [
        5,
        6,
        1
      ],
      "state": 3
    },
    {
      "pos": [
        5,
        6,
        2
      ],
      "state": 3
    },
    {
      "pos": [
        5,
        6,
        3
      ],
      "state": 3
    },
    {
      "pos": [
        5,
        6,
        4
      ],
      "state": 3
    },
    {
      "pos": [
        5,
        6,
        5
      ],
      "state": 3
    },
    {
      "pos": [
        5,
        6,
        6
      ],
      "state": 3
    },
    {
      "pos": [
        5,
        6,
        7
      ],
      "state": 3
    },
    {
      "pos": [
        5,
        6,
        8
      ],
      "state": 3
    },
    {
      "pos": [
        5,
        6,
        9
      ],
      "state": 3
    },
    {
      "pos": [
        5,
        6,
        10
      ],
      "state": 3
    },
    {
      "pos": [
        5,
        6,
        11
      ],
      "state": 3
    },
    {
      "pos": [
        5,
        6,
        12
      ],
      "state": 3
    },
    {
      "pos": [
        5,
        6,
        13
      ],
      "state": 3
    },
    {
      "pos": [
        5,
        6,
        14
      ],
      "state": 3
    },
    {
      "pos": [
        5,
        6,
        15
      ],
      "state": 3
    },
    {
      "pos": [
        5,
        6,
        16
      ],
      "state": 3
    },
    {
      "pos": [
        5,
        6,
        17
      ],
      "state": 3
    },
    {
      "pos": [
        5,
        6,
        18
      ],
      "state": 3
    },
    {
      "pos": [
        5,
        6,
        19
      ],
      "state": 3
    },
    {
      "pos": [
        5,
        6,
        20
      ],
      "state": 3
    },
    {
      "pos": [
        5,
        6,
        21
      ],
      "state": 3
    },
    {
      "pos": [
        5,
        6,
        22
      ],
      "state": 3
    },
    {
      "pos": [
        5,
        6,
        23
      ],
      "state": 2
    },
    {
      "pos": [
        5,
        7,
        0
      ],
      "state": 1
    },
    {
      "pos": [
        5,
        7,
        1
      ],
      "state": 1
    },
    {
      "pos": [
        5,
        7,
        2
      ],
      "state": 1
    },
    {
      "pos": [
        5,
        7,
        3
      ],
      "state": 1
    },
    {
      "pos": [
        5,
        7,
        4
      ],
      "state": 1
    },
    {
      "pos": [
        5,
        7,
        5
      ],
      "state": 1
    },
    {
      "pos": [
        5,
        7,
        6
      ],
      "state": 1
    },
    {
      "pos": [
        5,
        7,
        7
      ],
      "state": 1
    },
    {
      "pos": [
        5,
        7,
        8
      ],
      "state": 1
    },
    {
      "pos": [
        5,
        7,
        9
      ],
